[2024-08-18T09:47:33.181+0000] {local_task_job_runner.py:123} INFO - ::group::Pre task execution logs
[2024-08-18T09:47:33.192+0000] {taskinstance.py:2603} INFO - Dependencies all met for dep_context=non-requeueable deps ti=<TaskInstance: kafka2hive.process2hive manual__2024-08-18T09:47:32.659144+00:00 [queued]>
[2024-08-18T09:47:33.197+0000] {taskinstance.py:2603} INFO - Dependencies all met for dep_context=requeueable deps ti=<TaskInstance: kafka2hive.process2hive manual__2024-08-18T09:47:32.659144+00:00 [queued]>
[2024-08-18T09:47:33.198+0000] {taskinstance.py:2856} INFO - Starting attempt 1 of 2
[2024-08-18T09:47:33.206+0000] {taskinstance.py:2879} INFO - Executing <Task(SSHOperator): process2hive> on 2024-08-18 09:47:32.659144+00:00
[2024-08-18T09:47:33.209+0000] {standard_task_runner.py:72} INFO - Started process 138 to run task
[2024-08-18T09:47:33.212+0000] {standard_task_runner.py:104} INFO - Running: ['***', 'tasks', 'run', 'kafka2hive', 'process2hive', 'manual__2024-08-18T09:47:32.659144+00:00', '--job-id', '28', '--raw', '--subdir', 'DAGS_FOLDER/kafka2hive.py', '--cfg-path', '/tmp/tmp706eqitk']
[2024-08-18T09:47:33.213+0000] {standard_task_runner.py:105} INFO - Job 28: Subtask process2hive
[2024-08-18T09:47:33.247+0000] {task_command.py:467} INFO - Running <TaskInstance: kafka2hive.process2hive manual__2024-08-18T09:47:32.659144+00:00 [running]> on host 4fb2805ec1b8
[2024-08-18T09:47:33.300+0000] {taskinstance.py:3122} INFO - Exporting env vars: AIRFLOW_CTX_DAG_OWNER='ren294' AIRFLOW_CTX_DAG_ID='kafka2hive' AIRFLOW_CTX_TASK_ID='process2hive' AIRFLOW_CTX_EXECUTION_DATE='2024-08-18T09:47:32.659144+00:00' AIRFLOW_CTX_TRY_NUMBER='1' AIRFLOW_CTX_DAG_RUN_ID='manual__2024-08-18T09:47:32.659144+00:00'
[2024-08-18T09:47:33.301+0000] {taskinstance.py:731} INFO - ::endgroup::
[2024-08-18T09:47:33.310+0000] {ssh.py:151} INFO - Creating ssh_client
[2024-08-18T09:47:33.311+0000] {ssh.py:124} INFO - ssh_hook is not provided or invalid. Trying ssh_conn_id to create SSHHook.
[2024-08-18T09:47:33.317+0000] {base.py:84} INFO - Retrieving connection 'spark_conn'
[2024-08-18T09:47:33.318+0000] {ssh.py:304} WARNING - No Host Key Verification. This won't protect against Man-In-The-Middle attacks
[2024-08-18T09:47:33.319+0000] {ssh.py:348} INFO - Failed to connect. Sleeping before retry attempt 1
[2024-08-18T09:47:37.519+0000] {ssh.py:348} INFO - Failed to connect. Sleeping before retry attempt 2
[2024-08-18T09:47:42.481+0000] {taskinstance.py:3301} ERROR - Task failed with exception
Traceback (most recent call last):
  File "/home/airflow/.local/lib/python3.10/site-packages/airflow/models/taskinstance.py", line 767, in _execute_task
    result = _execute_callable(context=context, **execute_callable_kwargs)
  File "/home/airflow/.local/lib/python3.10/site-packages/airflow/models/taskinstance.py", line 733, in _execute_callable
    return ExecutionCallableRunner(
  File "/home/airflow/.local/lib/python3.10/site-packages/airflow/utils/operator_helpers.py", line 252, in run
    return self.func(*args, **kwargs)
  File "/home/airflow/.local/lib/python3.10/site-packages/airflow/models/baseoperator.py", line 406, in wrapper
    return func(self, *args, **kwargs)
  File "/home/airflow/.local/lib/python3.10/site-packages/airflow/providers/ssh/operators/ssh.py", line 190, in execute
    with self.get_ssh_client() as ssh_client:
  File "/home/airflow/.local/lib/python3.10/site-packages/airflow/providers/ssh/operators/ssh.py", line 152, in get_ssh_client
    return self.hook.get_conn()
  File "/home/airflow/.local/lib/python3.10/site-packages/airflow/providers/ssh/hooks/ssh.py", line 352, in get_conn
    for attempt in Retrying(
  File "/home/airflow/.local/lib/python3.10/site-packages/tenacity/__init__.py", line 443, in __iter__
    do = self.iter(retry_state=retry_state)
  File "/home/airflow/.local/lib/python3.10/site-packages/tenacity/__init__.py", line 376, in iter
    result = action(retry_state)
  File "/home/airflow/.local/lib/python3.10/site-packages/tenacity/__init__.py", line 418, in exc_check
    raise retry_exc.reraise()
  File "/home/airflow/.local/lib/python3.10/site-packages/tenacity/__init__.py", line 185, in reraise
    raise self.last_attempt.result()
  File "/usr/local/lib/python3.10/concurrent/futures/_base.py", line 451, in result
    return self.__get_result()
  File "/usr/local/lib/python3.10/concurrent/futures/_base.py", line 403, in __get_result
    raise self._exception
  File "/home/airflow/.local/lib/python3.10/site-packages/airflow/providers/ssh/hooks/ssh.py", line 359, in get_conn
    client.connect(**connect_kwargs)
  File "/home/airflow/.local/lib/python3.10/site-packages/paramiko/client.py", line 409, in connect
    raise NoValidConnectionsError(errors)
paramiko.ssh_exception.NoValidConnectionsError: [Errno None] Unable to connect to port 22 on 192.168.0.13
[2024-08-18T09:47:42.510+0000] {taskinstance.py:1225} INFO - Marking task as UP_FOR_RETRY. dag_id=kafka2hive, task_id=process2hive, run_id=manual__2024-08-18T09:47:32.659144+00:00, execution_date=20240818T094732, start_date=20240818T094733, end_date=20240818T094742
[2024-08-18T09:47:42.523+0000] {taskinstance.py:340} INFO - ::group::Post task execution logs
[2024-08-18T09:47:42.523+0000] {standard_task_runner.py:124} ERROR - Failed to execute job 28 for task process2hive ([Errno None] Unable to connect to port 22 on 192.168.0.13; 138)
Traceback (most recent call last):
  File "/home/airflow/.local/lib/python3.10/site-packages/airflow/task/task_runner/standard_task_runner.py", line 117, in _start_by_fork
    ret = args.func(args, dag=self.dag)
  File "/home/airflow/.local/lib/python3.10/site-packages/airflow/cli/cli_config.py", line 49, in command
    return func(*args, **kwargs)
  File "/home/airflow/.local/lib/python3.10/site-packages/airflow/utils/cli.py", line 115, in wrapper
    return f(*args, **kwargs)
  File "/home/airflow/.local/lib/python3.10/site-packages/airflow/cli/commands/task_command.py", line 483, in task_run
    task_return_code = _run_task_by_selected_method(args, _dag, ti)
  File "/home/airflow/.local/lib/python3.10/site-packages/airflow/cli/commands/task_command.py", line 256, in _run_task_by_selected_method
    return _run_raw_task(args, ti)
  File "/home/airflow/.local/lib/python3.10/site-packages/airflow/cli/commands/task_command.py", line 341, in _run_raw_task
    return ti._run_raw_task(
  File "/home/airflow/.local/lib/python3.10/site-packages/airflow/utils/session.py", line 97, in wrapper
    return func(*args, session=session, **kwargs)
  File "/home/airflow/.local/lib/python3.10/site-packages/airflow/models/taskinstance.py", line 2995, in _run_raw_task
    return _run_raw_task(
  File "/home/airflow/.local/lib/python3.10/site-packages/airflow/models/taskinstance.py", line 273, in _run_raw_task
    TaskInstance._execute_task_with_callbacks(
  File "/home/airflow/.local/lib/python3.10/site-packages/airflow/models/taskinstance.py", line 3149, in _execute_task_with_callbacks
    result = self._execute_task(context, task_orig)
  File "/home/airflow/.local/lib/python3.10/site-packages/airflow/models/taskinstance.py", line 3173, in _execute_task
    return _execute_task(self, context, task_orig)
  File "/home/airflow/.local/lib/python3.10/site-packages/airflow/models/taskinstance.py", line 767, in _execute_task
    result = _execute_callable(context=context, **execute_callable_kwargs)
  File "/home/airflow/.local/lib/python3.10/site-packages/airflow/models/taskinstance.py", line 733, in _execute_callable
    return ExecutionCallableRunner(
  File "/home/airflow/.local/lib/python3.10/site-packages/airflow/utils/operator_helpers.py", line 252, in run
    return self.func(*args, **kwargs)
  File "/home/airflow/.local/lib/python3.10/site-packages/airflow/models/baseoperator.py", line 406, in wrapper
    return func(self, *args, **kwargs)
  File "/home/airflow/.local/lib/python3.10/site-packages/airflow/providers/ssh/operators/ssh.py", line 190, in execute
    with self.get_ssh_client() as ssh_client:
  File "/home/airflow/.local/lib/python3.10/site-packages/airflow/providers/ssh/operators/ssh.py", line 152, in get_ssh_client
    return self.hook.get_conn()
  File "/home/airflow/.local/lib/python3.10/site-packages/airflow/providers/ssh/hooks/ssh.py", line 352, in get_conn
    for attempt in Retrying(
  File "/home/airflow/.local/lib/python3.10/site-packages/tenacity/__init__.py", line 443, in __iter__
    do = self.iter(retry_state=retry_state)
  File "/home/airflow/.local/lib/python3.10/site-packages/tenacity/__init__.py", line 376, in iter
    result = action(retry_state)
  File "/home/airflow/.local/lib/python3.10/site-packages/tenacity/__init__.py", line 418, in exc_check
    raise retry_exc.reraise()
  File "/home/airflow/.local/lib/python3.10/site-packages/tenacity/__init__.py", line 185, in reraise
    raise self.last_attempt.result()
  File "/usr/local/lib/python3.10/concurrent/futures/_base.py", line 451, in result
    return self.__get_result()
  File "/usr/local/lib/python3.10/concurrent/futures/_base.py", line 403, in __get_result
    raise self._exception
  File "/home/airflow/.local/lib/python3.10/site-packages/airflow/providers/ssh/hooks/ssh.py", line 359, in get_conn
    client.connect(**connect_kwargs)
  File "/home/airflow/.local/lib/python3.10/site-packages/paramiko/client.py", line 409, in connect
    raise NoValidConnectionsError(errors)
paramiko.ssh_exception.NoValidConnectionsError: [Errno None] Unable to connect to port 22 on 192.168.0.13
[2024-08-18T09:47:42.532+0000] {local_task_job_runner.py:261} INFO - Task exited with return code 1
[2024-08-18T09:47:42.542+0000] {taskinstance.py:3891} INFO - 0 downstream tasks scheduled from follow-on schedule check
[2024-08-18T09:47:42.544+0000] {local_task_job_runner.py:240} INFO - ::endgroup::
